<mujoco model="coffee-gimbal">

    <compiler angle="radian" coordinate="local"/>
    <option viscosity="0.2"/>
<!--    <option timestep="0.002"/>-->
<!--    iterations="100"-->


    <default>
        <joint damping="0.1" />
        <geom friction=".5"/>
    </default>

    <asset>
        <mesh name="bottom_segment_mesh" file="mesh/bottom_segment_1mm.stl"/>
        <mesh name="x_arm_mesh" file="mesh/x_arm.stl"/>
        <mesh name="y_arm_mesh" file="mesh/y_arm.stl"/>
    </asset>

    <worldbody>
        <light pos="0 -0.25 1"/>
        <geom type="plane" size="1 1 .01" pos="0 0 -.05"/>



        <body name="y_arm" pos="0 0 0">
            <joint name="move_x" type="slide" axis="1 0 0" range="-0.2 0.2" damping="5"/>
            <joint name="move_y" type="slide" axis="0 1 0" range="-0.2 0.2" damping="5"/>

            <geom type="mesh" mesh="y_arm_mesh"
                  rgba="0.32 0.87 0.16 1"
                  contype="0"
                  conaffinity="0"/>

            <body name="x_arm" pos="0 0 0">
                <joint name="rot_y" type="hinge" axis="1 0 0" pos="0 0 0.071"/>

                <geom type="mesh" mesh="x_arm_mesh"
                      rgba="0.87 0.32 0.16 1"
                      contype="0"
                      conaffinity="0"
/>

                 <body name="mug_bottom" pos="0 0 0.066">
                    <joint name="rot_x" type="hinge" axis="0 1 0" pos="0 0 0.01"/>

                     <replicate count="18" euler="0 0 0.349">
                         <geom type="mesh" mesh="bottom_segment_mesh"
                          rgba="0.92 0.92 0.92 1"/>
                     </replicate>
                </body>
            </body>
        </body>

          <body name="ball" pos="0 0 0.075">
                <freejoint/>
                <geom type="sphere" size="0.01" rgba="1 0 0 1" margin="0.02" gap=".02" mass="0.1"/>

            </body>


    </worldbody>

    <actuator>
        <position name="move_x" joint="move_x" kp="30" ctrlrange="-.2 .2"/>
        <position name="move_y" joint="move_y" kp="30" ctrlrange="-.2 .2"/>
        <position name="rot_x" joint="rot_x" kp="10" timeconst="0.025" ctrlrange="-1.57 1.57"/>
        <position name="rot_y" joint="rot_y" kp="10" timeconst="0.025" ctrlrange="-1.57 1.57"/>
    </actuator>


</mujoco>
