<mujoco model="coffee-gimbal">

    <compiler angle="radian" coordinate="local"/>

    <option timestep="0.001"
    iterations="100"
    />

    <default>
        <joint damping="1"/>
        <geom  friction="1 0.005 0.0001"
               density="1000"
               margin="0.001"
               contype="1"
               conaffinity="1"
               solimp="0.99 0.99 0.01" solref="0.001 1"
        />
    </default>

    <asset>
        <mesh name="mug_segment_mesh" file="mesh/mug_segment.stl"/>
        <mesh name="bottom_segment_mesh" file="mesh/bottom_segment.stl"/>
        <mesh name="x_arm_mesh" file="mesh/x_arm.stl"/>
        <mesh name="y_arm_mesh" file="mesh/y_arm.stl"/>
    </asset>

    <worldbody>
        <light pos="0 -0.25 1"/>
        <geom type="plane" size="1 1 .01" pos="0 0 -.05"/>



        <body name="y_arm" pos="0 0 0">
            <joint name="move_x" type="slide" axis="1 0 0" damping="100" range="-0.2 0.2"/>
            <joint name="move_y" type="slide" axis="0 1 0" damping="100" range="-0.2 0.2"/>

            <geom type="mesh" mesh="y_arm_mesh"
                  rgba="0.32 0.87 0.16 1"
                  mass="0.1"
                  contype="0"
                  conaffinity="0"/>

            <body name="x_arm" pos="0 0 0">
                <joint name="rot_y" type="hinge" axis="1 0 0" pos="0 0 0.071" range="-0.5 0.5"/>

                <geom type="mesh" mesh="x_arm_mesh"
                      rgba="0.87 0.32 0.16 1"
                      mass="0.1"
                      contype="0"
                      conaffinity="0"
/>

                 <body name="mug_segment" pos="0 0 0">
                    <joint name="rot_x" type="hinge" axis="0 1 0" pos="0 0 0.071" range="-0.05 0.05"/>

                     <replicate count="18" euler="0 0 0.349">
                        <geom type="mesh" mesh="mug_segment_mesh"
                          rgba="0.92 0.92 0.92 1"/>
                         <geom type="mesh" mesh="bottom_segment_mesh"
                          rgba="0.92 0.92 0.92 1"/>
                     </replicate>
                </body>
            </body>
        </body>

          <body name="ball" pos="0 0 0.3">
                <joint type="free" damping="0.0001" />
                <geom type="sphere" size="0.01" rgba="1 0 0 1" mass="0.05" />
<!--                      solref="-1000 0"/>-->
            </body>


    </worldbody>

    <actuator>
        <position name="f_x force" joint="move_x" kp="1000" ctrlrange="-.2 .2"/>
        <position name="f_y force" joint="move_y" kp="1000" ctrlrange="-.2 .2"/>
        <position name="tau_x torque" joint="rot_x" kp="50"/>
        <position name="tau_y torque" joint="rot_y" kp="50"/>
    </actuator>


</mujoco>
